[2024-04-11 23:23:44,906: INFO: config: PyTorch version 2.2.2+cu121 available.]
[2024-04-11 23:23:48,058: INFO: main: >>>>>> stage Data Ingestion stage started <<<<<<]
[2024-04-11 23:23:48,061: INFO: common: yaml file: config\config.yaml loaded successfully]
[2024-04-11 23:23:48,063: INFO: common: yaml file: params.yaml loaded successfully]
[2024-04-11 23:23:48,064: INFO: common: created directory at: artifacts]
[2024-04-11 23:23:48,065: INFO: common: created directory at: artifacts/data_ingestion]
[2024-04-11 23:23:48,066: INFO: data_ingestion: File already exists of size: ~ 7718 KB]
[2024-04-11 23:23:48,204: INFO: data_ingestion: Extraction Compelete]
[2024-04-11 23:23:48,205: INFO: main: >>>>>> stage Data Ingestion stage completed <<<<<<

x==========x]
[2024-04-11 23:23:48,205: INFO: main: >>>>>> stage Data Validation stage started <<<<<<]
[2024-04-11 23:23:48,212: INFO: common: yaml file: config\config.yaml loaded successfully]
[2024-04-11 23:23:48,216: INFO: common: yaml file: params.yaml loaded successfully]
[2024-04-11 23:23:48,216: INFO: common: created directory at: artifacts]
[2024-04-11 23:23:48,217: INFO: common: created directory at: artifacts/data_validation]
[2024-04-11 23:23:48,219: INFO: main: >>>>>> stage Data Validation stage completed <<<<<<

x==========x]
[2024-04-11 23:23:48,219: INFO: main: >>>>>> stage Data Transformation stage started <<<<<<]
[2024-04-11 23:23:48,224: INFO: common: yaml file: config\config.yaml loaded successfully]
[2024-04-11 23:23:48,226: INFO: common: yaml file: params.yaml loaded successfully]
[2024-04-11 23:23:48,227: INFO: common: created directory at: artifacts]
[2024-04-11 23:23:48,228: INFO: common: created directory at: artifacts/data_transformation]
[2024-04-11 23:23:49,299: INFO: main: >>>>>> stage Data Transformation stage completed <<<<<<

x==========x]
[2024-04-11 23:23:49,300: INFO: main: >>>>>> stage Model evaluation stage started <<<<<<]
[2024-04-11 23:23:49,303: INFO: common: yaml file: config\config.yaml loaded successfully]
[2024-04-11 23:23:49,305: INFO: common: yaml file: params.yaml loaded successfully]
[2024-04-11 23:23:49,306: INFO: common: created directory at: artifacts]
[2024-04-11 23:23:49,306: ERROR: main: "'ConfigBox' object has no attribute 'model_evaluation'"]
Traceback (most recent call last):
  File "box\box.py", line 503, in box.box.Box.__getitem__
KeyError: 'model_evaluation'

The above exception was the direct cause of the following exception:

Traceback (most recent call last):
  File "box\box.py", line 536, in box.box.Box.__getattr__
  File "box\box.py", line 524, in box.box.Box.__getitem__
box.exceptions.BoxKeyError: "'model_evaluation'"

During handling of the above exception, another exception occurred:

Traceback (most recent call last):
  File "box\box.py", line 538, in box.box.Box.__getattr__
AttributeError: 'ConfigBox' object has no attribute 'model_evaluation'

The above exception was the direct cause of the following exception:

Traceback (most recent call last):
  File "box\config_box.py", line 28, in box.config_box.ConfigBox.__getattr__
  File "box\box.py", line 552, in box.box.Box.__getattr__
box.exceptions.BoxKeyError: "'ConfigBox' object has no attribute 'model_evaluation'"

During handling of the above exception, another exception occurred:

Traceback (most recent call last):
  File "box\box.py", line 503, in box.box.Box.__getitem__
KeyError: 'model_evaluation'

The above exception was the direct cause of the following exception:

Traceback (most recent call last):
  File "box\box.py", line 536, in box.box.Box.__getattr__
  File "box\box.py", line 524, in box.box.Box.__getitem__
box.exceptions.BoxKeyError: "'model_evaluation'"

During handling of the above exception, another exception occurred:

Traceback (most recent call last):
  File "box\box.py", line 538, in box.box.Box.__getattr__
AttributeError: 'ConfigBox' object has no attribute 'model_evaluation'

The above exception was the direct cause of the following exception:

Traceback (most recent call last):
  File "main.py", line 62, in <module>
    model_evaluation.main()
  File "c:\users\hites\onedrive\desktop\end to end ml project\text-summarization-nlp-project\src\textSummarizer\pipeline\model_evaluation.py", line 10, in main
    model_evaluation_config = config.get_model_evaluation_config()
  File "c:\users\hites\onedrive\desktop\end to end ml project\text-summarization-nlp-project\src\textSummarizer\config\configuration.py", line 82, in get_model_evaluation_config
    config = self.config.model_evaluation
  File "box\config_box.py", line 30, in box.config_box.ConfigBox.__getattr__
  File "box\box.py", line 552, in box.box.Box.__getattr__
box.exceptions.BoxKeyError: "'ConfigBox' object has no attribute 'model_evaluation'"
